Workbook

Sheet Data
A1: Treatment | B1: Rotation | C1: Year | D1: Region | E1: Soil PAWC | F1: Time of break | G1: Quality of break | H1: Spring rainfall decile | I1: GS rainfall decile | J1: 3 Previous Land Use | K1: 2 Previous Land Use | L1: Previous Land Use | M1: Current Land Use | N1: =J1&" N Level" -> 3 Previous Land Use N Level | O1: =K1&" N Level" -> 2 Previous Land Use N Level | P1: =L1&" N Level" -> Previous Land Use N Level | Q1: N Rate (kg N/ha) | R1: Yield (t/ha) | S1: Protein (%) | T1: Screenings (%) | U1: Grain Nitrogen % | V1: Nitrogen Removal | W1: NUE (yield Nf) | X1: Total available soil N (kg/ha)
A2: H | B2: No Legume | C2: 2023 | D2: Kendenup | E2: Medium | F2: Late | G2: Poor | H2: Poor | I2: Good | M2: Wheat | Q2: 146.2 | R2: 3.281471 | S2: 11.1 | T2: 4.5588514 | U2: =S2/VLOOKUP(M2,Constants!$A$2:$B$5,2,FALSE) -> 1.9137931 | V2: =U2/100*R2*1000 -> 62.800566 | W2: =V2/Q2 -> 0.42955243 | X2: 87.56
A3: L | B3: No Legume | C3: 2023 | D3: Kendenup | E3: Medium | F3: Late | G3: Poor | H3: Poor | I3: Good | M3: Wheat | Q3: 79.2 | R3: 2.9816124 | S3: 9.8 | T3: 3.594812 | U3: =S3/VLOOKUP(M3,Constants!$A$2:$B$5,2,FALSE) -> 1.6896552 | V3: =U3/100*R3*1000 -> 50.378969 | W3: =V3/Q3 -> 0.63609809 | X3: 87.95
A4: N | B4: No Legume | C4: 2023 | D4: Kendenup | E4: Medium | F4: Late | G4: Poor | H4: Poor | I4: Good | M4: Wheat | Q4: 10 | R4: 2.1669024 | S4: 9.4 | T4: 2.2471319 | U4: =S4/VLOOKUP(M4,Constants!$A$2:$B$5,2,FALSE) -> 1.6206897 | V4: =U4/100*R4*1000 -> 35.118763 | W4: =V4/Q4 -> 3.5118763 | X4: 99.81
A5: N | B5: No Legume | C5: 2023 | D5: Kendenup | E5: Medium | F5: Late | G5: Poor | H5: Poor | I5: Good | M5: Canola | Q5: 10 | R5: 0.99009901 | S5: 19.5 | T5: 0 | U5: =S5/VLOOKUP(M5,Constants!$A$2:$B$5,2,FALSE) -> 3.12 | V5: =U5/100*R5*1000 -> 30.891089 | W5: =V5/Q5 -> 3.0891089 | X5: 63.65
A6: L | B6: No Legume | C6: 2023 | D6: Kendenup | E6: Medium | F6: Late | G6: Poor | H6: Poor | I6: Good | M6: Canola | Q6: 75.2 | R6: 1.2050919 | S6: 19.6 | T6: 0 | U6: =S6/VLOOKUP(M6,Constants!$A$2:$B$5,2,FALSE) -> 3.136 | V6: =U6/100*R6*1000 -> 37.791683 | W6: =V6/Q6 -> 0.50254898 | X6: 121.58
A7: H | B7: No Legume | C7: 2023 | D7: Kendenup | E7: Medium | F7: Late | G7: Poor | H7: Poor | I7: Good | M7: Canola | Q7: 175.2 | R7: 1.6237624 | S7: 20.8 | T7: 0 | U7: =S7/VLOOKUP(M7,Constants!$A$2:$B$5,2,FALSE) -> 3.328 | V7: =U7/100*R7*1000 -> 54.038812 | W7: =V7/Q7 -> 0.30844071 | X7: 83.3
A8: N | B8: Single Break | C8: 2023 | D8: Kendenup | E8: Medium | F8: Late | G8: Poor | H8: Poor | I8: Good | M8: Wheat | Q8: 10 | R8: 1.5615276 | S8: 10.1 | T8: 3.4128005 | U8: =S8/VLOOKUP(M8,Constants!$A$2:$B$5,2,FALSE) -> 1.7413793 | V8: =U8/100*R8*1000 -> 27.192118 | W8: =V8/Q8 -> 2.7192118 | X8: 68.11
A9: H | B9: Single Break | C9: 2023 | D9: Kendenup | E9: Medium | F9: Late | G9: Poor | H9: Poor | I9: Good | M9: Wheat | Q9: 146.2 | R9: 2.330976 | S9: 11.2 | T9: 4.3620712 | U9: =S9/VLOOKUP(M9,Constants!$A$2:$B$5,2,FALSE) -> 1.9310345 | V9: =U9/100*R9*1000 -> 45.011949 | W9: =V9/Q9 -> 0.30787927 | X9: 73.85
A10: L | B10: Single Break | C10: 2023 | D10: Kendenup | E10: Medium | F10: Late | G10: Poor | H10: Poor | I10: Good | M10: Wheat | Q10: 79.2 | R10: 1.9009901 | S10: 10.6 | T10: 3.8078451 | U10: =S10/VLOOKUP(M10,Constants!$A$2:$B$5,2,FALSE) -> 1.8275862 | V10: =U10/100*R10*1000 -> 34.742233 | W10: =V10/Q10 -> 0.43866456 | X10: 77.1
A11: L | B11: Single Break | C11: 2023 | D11: Kendenup | E11: Medium | F11: Late | G11: Poor | H11: Poor | I11: Good | M11: Canola | Q11: 75.2 | R11: 1.397454 | S11: 19.4 | T11: 0 | U11: =S11/VLOOKUP(M11,Constants!$A$2:$B$5,2,FALSE) -> 3.104 | V11: =U11/100*R11*1000 -> 43.376973 | W11: =V11/Q11 -> 0.57682145
A12: N | B12: Single Break | C12: 2023 | D12: Kendenup | E12: Medium | F12: Late | G12: Poor | H12: Poor | I12: Good | M12: Canola | Q12: 10 | R12: 1.0127298 | S12: 20.3 | T12: 0 | U12: =S12/VLOOKUP(M12,Constants!$A$2:$B$5,2,FALSE) -> 3.248 | V12: =U12/100*R12*1000 -> 32.893465 | W12: =V12/Q12 -> 3.2893465
A13: H | B13: Single Break | C13: 2023 | D13: Kendenup | E13: Medium | F13: Late | G13: Poor | H13: Poor | I13: Good | M13: Canola | Q13: 175.2 | R13: 1.5502122 | S13: 20.8 | T13: 0 | U13: =S13/VLOOKUP(M13,Constants!$A$2:$B$5,2,FALSE) -> 3.328 | V13: =U13/100*R13*1000 -> 51.591061 | W13: =V13/Q13 -> 0.29446953
A14: H | B14: Single Break | C14: 2023 | D14: Kendenup | E14: Medium | F14: Late | G14: Poor | H14: Poor | I14: Good | M14: Barley | Q14: 146.2 | R14: 3.8019802 | S14: 12.2 | T14: 2.1453058 | U14: =S14/VLOOKUP(M14,Constants!$A$2:$B$5,2,FALSE) -> 2.1746881 | V14: =U14/100*R14*1000 -> 82.681209 | W14: =V14/Q14 -> 0.56553495 | X14: 91.11
A15: N | B15: Single Break | C15: 2023 | D15: Kendenup | E15: Medium | F15: Late | G15: Poor | H15: Poor | I15: Good | M15: Barley | Q15: 10 | R15: 2.1725601 | S15: 10.5 | T15: 2.8575994 | U15: =S15/VLOOKUP(M15,Constants!$A$2:$B$5,2,FALSE) -> 1.8716578 | V15: =U15/100*R15*1000 -> 40.66289 | W15: =V15/Q15 -> 4.066289 | X15: 54.6
A16: L | B16: Single Break | C16: 2023 | D16: Kendenup | E16: Medium | F16: Late | G16: Poor | H16: Poor | I16: Good | M16: Barley | Q16: 79.2 | R16: 3.1739745 | S16: 11.4 | T16: 3.0097246 | U16: =S16/VLOOKUP(M16,Constants!$A$2:$B$5,2,FALSE) -> 2.0320856 | V16: =U16/100*R16*1000 -> 64.497878 | W16: =V16/Q16 -> 0.81436715 | X16: 44.74
A17: N | B17: Single Break | C17: 2023 | D17: Kendenup | E17: Medium | F17: Late | G17: Poor | H17: Poor | I17: Good | M17: Lupin | Q17: 10 | R17: 2.8005658 | S17: 29.1 | T17: 0 | U17: =S17/VLOOKUP(M17,Constants!$A$2:$B$5,2,FALSE) -> 4.656 | V17: =U17/100*R17*1000 -> 130.39434 | W17: =V17/Q17 -> 13.039434 | X17: 103.7
A18: H | B18: Single Break | C18: 2023 | D18: Kendenup | E18: Medium | F18: Late | G18: Poor | H18: Poor | I18: Good | M18: Lupin | Q18: 10 | R18: 2.5007072 | S18: 29.7 | T18: 0 | U18: =S18/VLOOKUP(M18,Constants!$A$2:$B$5,2,FALSE) -> 4.752 | V18: =U18/100*R18*1000 -> 118.83361 | W18: =V18/Q18 -> 11.883361 | X18: 67.28
A19: L | B19: Single Break | C19: 2023 | D19: Kendenup | E19: Medium | F19: Late | G19: Poor | H19: Poor | I19: Good | M19: Lupin | Q19: 10 | R19: 2.7779349 | S19: 29 | T19: 0 | U19: =S19/VLOOKUP(M19,Constants!$A$2:$B$5,2,FALSE) -> 4.64 | V19: =U19/100*R19*1000 -> 128.89618 | W19: =V19/Q19 -> 12.889618
A20: L | B20: Double Break | C20: 2023 | D20: Kendenup | E20: Medium | F20: Late | G20: Poor | H20: Poor | I20: Good | M20: Lupin | Q20: 10 | R20: 1.9915134 | S20: 33 | T20: 0 | U20: =S20/VLOOKUP(M20,Constants!$A$2:$B$5,2,FALSE) -> 5.28 | V20: =U20/100*R20*1000 -> 105.15191 | W20: =V20/Q20 -> 10.515191
A21: H | B21: Double Break | C21: 2023 | D21: Kendenup | E21: Medium | F21: Late | G21: Poor | H21: Poor | I21: Good | M21: Lupin | Q21: 10 | R21: 2.2743989 | S21: 29.4 | T21: 0 | U21: =S21/VLOOKUP(M21,Constants!$A$2:$B$5,2,FALSE) -> 4.704 | V21: =U21/100*R21*1000 -> 106.98772 | W21: =V21/Q21 -> 10.698772
A22: N | B22: Double Break | C22: 2023 | D22: Kendenup | E22: Medium | F22: Late | G22: Poor | H22: Poor | I22: Good | M22: Lupin | Q22: 10 | R22: 2.1442716 | S22: 29.3 | T22: 0 | U22: =S22/VLOOKUP(M22,Constants!$A$2:$B$5,2,FALSE) -> 4.688 | V22: =U22/100*R22*1000 -> 100.52345 | W22: =V22/Q22 -> 10.052345
A23: N | B23: Double Break | C23: 2023 | D23: Kendenup | E23: Medium | F23: Late | G23: Poor | H23: Poor | I23: Good | M23: Canola | Q23: 10 | R23: 0.3960396 | S23: 21.4 | T23: 0 | U23: =S23/VLOOKUP(M23,Constants!$A$2:$B$5,2,FALSE) -> 3.424 | V23: =U23/100*R23*1000 -> 13.560396 | W23: =V23/Q23 -> 1.3560396
A24: L | B24: Double Break | C24: 2023 | D24: Kendenup | E24: Medium | F24: Late | G24: Poor | H24: Poor | I24: Good | M24: Canola | Q24: 75.2 | R24: 0.7864215 | S24: 21.6 | T24: 0 | U24: =S24/VLOOKUP(M24,Constants!$A$2:$B$5,2,FALSE) -> 3.456 | V24: =U24/100*R24*1000 -> 27.178727 | W24: =V24/Q24 -> 0.36141924
A25: H | B25: Double Break | C25: 2023 | D25: Kendenup | E25: Medium | F25: Late | G25: Poor | H25: Poor | I25: Good | M25: Canola | Q25: 175.2 | R25: 1.0862801 | S25: 21.9 | T25: 0 | U25: =S25/VLOOKUP(M25,Constants!$A$2:$B$5,2,FALSE) -> 3.504 | V25: =U25/100*R25*1000 -> 38.063253 | W25: =V25/Q25 -> 0.21725601
A26: N | B26: Double Break | C26: 2023 | D26: Kendenup | E26: Medium | F26: Late | G26: Poor | H26: Poor | I26: Good | M26: Barley | Q26: 10 | R26: 1.3125884 | S26: 9.4 | T26: 2.2883672 | U26: =S26/VLOOKUP(M26,Constants!$A$2:$B$5,2,FALSE) -> 1.6755793 | V26: =U26/100*R26*1000 -> 21.99346 | W26: =V26/Q26 -> 2.199346 | X26: 60.53
A27: L | B27: Double Break | C27: 2023 | D27: Kendenup | E27: Medium | F27: Late | G27: Poor | H27: Poor | I27: Good | M27: Barley | Q27: 79.2 | R27: 2.5063649 | S27: 11.2 | T27: 4.0408016 | U27: =S27/VLOOKUP(M27,Constants!$A$2:$B$5,2,FALSE) -> 1.9964349 | V27: =U27/100*R27*1000 -> 50.037945 | W27: =V27/Q27 -> 0.63179223 | X27: 61.505
A28: H | B28: Double Break | C28: 2023 | D28: Kendenup | E28: Medium | F28: Late | G28: Poor | H28: Poor | I28: Good | M28: Barley | Q28: 146.2 | R28: 2.0367751 | S28: 11.8 | T28: 3.7438038 | U28: =S28/VLOOKUP(M28,Constants!$A$2:$B$5,2,FALSE) -> 2.1033868 | V28: =U28/100*R28*1000 -> 42.841259 | W28: =V28/Q28 -> 0.29303187 | X28: 52.885
A29: H | B29: Double Break | C29: 2023 | D29: Kendenup | E29: Medium | F29: Late | G29: Poor | H29: Poor | I29: Good | M29: Wheat | Q29: 146.2 | R29: 2.1442716 | S29: 11.6 | T29: 4.5131357 | U29: =S29/VLOOKUP(M29,Constants!$A$2:$B$5,2,FALSE) -> 2 | V29: =U29/100*R29*1000 -> 42.885431 | W29: =V29/Q29 -> 0.293334
A30: L | B30: Double Break | C30: 2023 | D30: Kendenup | E30: Medium | F30: Late | G30: Poor | H30: Poor | I30: Good | M30: Wheat | Q30: 79.2 | R30: 2.2574257 | S30: 10.1 | T30: 3.9294282 | U30: =S30/VLOOKUP(M30,Constants!$A$2:$B$5,2,FALSE) -> 1.7413793 | V30: =U30/100*R30*1000 -> 39.310345 | W30: =V30/Q30 -> 0.49634274
A31: N | B31: Double Break | C31: 2023 | D31: Kendenup | E31: Medium | F31: Late | G31: Poor | H31: Poor | I31: Good | M31: Wheat | Q31: 10 | R31: 1.6011315 | S31: 9.8 | T31: 0.42999874 | U31: =S31/VLOOKUP(M31,Constants!$A$2:$B$5,2,FALSE) -> 1.6896552 | V31: =U31/100*R31*1000 -> 27.053602 | W31: =V31/Q31 -> 2.7053602
A32: H | B32: Single Break | C32: 2023 | D32: Kendenup | E32: Medium | F32: Late | G32: Poor | H32: Poor | I32: Good | M32: Barley | Q32: 146.2 | R32: 4.3485714 | S32: 11.1 | T32: 2.808907 | U32: =S32/VLOOKUP(M32,Constants!$A$2:$B$5,2,FALSE) -> 1.9786096 | V32: =U32/100*R32*1000 -> 86.041253 | W32: =V32/Q32 -> 0.58851746 | X32: 74.27
A33: N | B33: Single Break | C33: 2023 | D33: Kendenup | E33: Medium | F33: Late | G33: Poor | H33: Poor | I33: Good | M33: Barley | Q33: 10 | R33: 2.9485714 | S33: 9.8 | T33: 1.3256288 | U33: =S33/VLOOKUP(M33,Constants!$A$2:$B$5,2,FALSE) -> 1.7468806 | V33: =U33/100*R33*1000 -> 51.508021 | W33: =V33/Q33 -> 5.1508021 | X33: 48.55
A34: L | B34: Single Break | C34: 2023 | D34: Kendenup | E34: Medium | F34: Late | G34: Poor | H34: Poor | I34: Good | M34: Barley | Q34: 79.2 | R34: 4.16 | S34: 10.4 | T34: 2.5460744 | U34: =S34/VLOOKUP(M34,Constants!$A$2:$B$5,2,FALSE) -> 1.8538324 | V34: =U34/100*R34*1000 -> 77.11943 | W34: =V34/Q34 -> 0.97373017 | X34: 60.54
A35: L | B35: Double Break | C35: 2023 | D35: Kendenup | E35: Medium | F35: Late | G35: Poor | H35: Poor | I35: Good | M35: Lupin | Q35: 10 | R35: 2.8114286 | S35: 29.3 | T35: 0 | U35: =S35/VLOOKUP(M35,Constants!$A$2:$B$5,2,FALSE) -> 4.688 | V35: =U35/100*R35*1000 -> 131.79977 | W35: =V35/Q35 -> 13.179977
A36: H | B36: Double Break | C36: 2023 | D36: Kendenup | E36: Medium | F36: Late | G36: Poor | H36: Poor | I36: Good | M36: Lupin | Q36: 10 | R36: 3.3314286 | S36: 33.2 | T36: 0 | U36: =S36/VLOOKUP(M36,Constants!$A$2:$B$5,2,FALSE) -> 5.312 | V36: =U36/100*R36*1000 -> 176.96549 | W36: =V36/Q36 -> 17.696549
A37: N | B37: Double Break | C37: 2023 | D37: Kendenup | E37: Medium | F37: Late | G37: Poor | H37: Poor | I37: Good | M37: Lupin | Q37: 10 | R37: 3.2685714 | S37: 28.9 | T37: 0 | U37: =S37/VLOOKUP(M37,Constants!$A$2:$B$5,2,FALSE) -> 4.624 | V37: =U37/100*R37*1000 -> 151.13874 | W37: =V37/Q37 -> 15.113874
A38: N | B38: Double Break | C38: 2023 | D38: Kendenup | E38: Medium | F38: Late | G38: Poor | H38: Poor | I38: Good | M38: Canola | Q38: 10 | R38: 0.96 | S38: 18.9 | T38: 0 | U38: =S38/VLOOKUP(M38,Constants!$A$2:$B$5,2,FALSE) -> 3.024 | V38: =U38/100*R38*1000 -> 29.0304 | W38: =V38/Q38 -> 2.90304
A39: H | B39: Double Break | C39: 2023 | D39: Kendenup | E39: Medium | F39: Late | G39: Poor | H39: Poor | I39: Good | M39: Canola | Q39: 175.2 | R39: 1.5257143 | S39: 20 | T39: 0 | U39: =S39/VLOOKUP(M39,Constants!$A$2:$B$5,2,FALSE) -> 3.2 | V39: =U39/100*R39*1000 -> 48.822857 | W39: =V39/Q39 -> 0.27866928
A40: L | B40: Double Break | C40: 2023 | D40: Kendenup | E40: Medium | F40: Late | G40: Poor | H40: Poor | I40: Good | M40: Canola | Q40: 75.2 | R40: 1.3828571 | S40: 18.8 | T40: 0 | U40: =S40/VLOOKUP(M40,Constants!$A$2:$B$5,2,FALSE) -> 3.008 | V40: =U40/100*R40*1000 -> 41.596343 | W40: =V40/Q40 -> 0.55314286
...

Sheet Constants
B1: N conversion factor
A2: Lupin | B2: 6.25
A3: Wheat | B3: 5.8
A4: Barley | B4: 5.61
A5: Canola | B5: 6.25
